[0;33m--- idf_monitor on /dev/ttyUSB0 115200 ---[0m
[0;33m--- Quit: Ctrl+] | Menu: Ctrl+T | Help: Ctrl+T followed by Ctrl+H ---[0m
Exception in thread Thread-2 (_run_outer):
Traceback (most recent call last):
  File "threading.py", line 1038, in _bootstrap_inner
  File "threading.py", line 975, in run
  File "E:\Q_R2\Espressif\python_env\idf5.1_py3.11_env\Lib\site-packages\esp_idf_monitor\base\stoppable_thread.py", line 47, in _run_outer
    self.run()
  File "E:\Q_R2\Espressif\python_env\idf5.1_py3.11_env\Lib\site-packages\esp_idf_monitor\base\serial_reader.py", line 53, in run
    self.serial.open()
  File "E:\Q_R2\Espressif\python_env\idf5.1_py3.11_env\Lib\site-packages\serial\serialwin32.py", line 64, in open
    raise SerialException("could not open port {!r}: {!r}".format(self.portstr, ctypes.WinError()))
serial.serialutil.SerialException: could not open port '/dev/ttyUSB0': FileNotFoundError(2, '系统找不到指定的路径。', None, 3)
[0m
